[2023-12-10 10:11:22,078][__main__][INFO] - For logs, checkpoints and samples check /Volumes/Castile/HackerProj/denoiser
[2023-12-10 10:11:27,999][denoiser.solver][INFO] - ----------------------------------------------------------------------
[2023-12-10 10:11:27,999][denoiser.solver][INFO] - Training...
[2023-12-10 10:11:56,501][denoiser.solver][INFO] - Train | Epoch 1 | 1/1 | 14.2 sec/it | Loss inf
[2023-12-10 10:11:56,505][denoiser.solver][INFO] - [1mTrain Summary | End of Epoch 1 | Time 28.51s | Train Loss inf[0m
[2023-12-10 10:11:56,506][denoiser.solver][INFO] - ----------------------------------------------------------------------
[2023-12-10 10:11:56,506][denoiser.solver][INFO] - Cross validation...
[2023-12-10 10:12:00,134][denoiser.solver][INFO] - Valid | Epoch 1 | 5/25 | 1.7 it/sec | Loss inf
[2023-12-10 10:12:00,536][denoiser.solver][INFO] - Valid | Epoch 1 | 10/25 | 2.8 it/sec | Loss inf
[2023-12-10 10:12:00,952][denoiser.solver][INFO] - Valid | Epoch 1 | 15/25 | 3.6 it/sec | Loss inf
[2023-12-10 10:12:01,345][denoiser.solver][INFO] - Valid | Epoch 1 | 20/25 | 4.4 it/sec | Loss inf
[2023-12-10 10:12:26,790][denoiser.solver][INFO] - Valid | Epoch 1 | 25/25 | 0.9 it/sec | Loss inf
[2023-12-10 10:12:26,792][denoiser.solver][INFO] - [1mValid Summary | End of Epoch 1 | Time 58.79s | Valid Loss inf[0m
[2023-12-10 10:12:26,792][denoiser.solver][INFO] - [1mNew best valid loss inf[0m
[2023-12-10 10:12:26,838][denoiser.solver][INFO] - ----------------------------------------------------------------------
[2023-12-10 10:12:26,838][denoiser.solver][INFO] - [1mOverall Summary | Epoch 1 | Train inf | Valid inf | Best inf[0m
[2023-12-10 10:12:26,839][__main__][ERROR] - Some error happened
Traceback (most recent call last):
  File "/Volumes/Castile/HackerProj/denoiser/train.py", line 121, in main
    _main(args)
  File "/Volumes/Castile/HackerProj/denoiser/train.py", line 114, in _main
    run(args)
  File "/Volumes/Castile/HackerProj/denoiser/train.py", line 95, in run
    solver.train()
  File "/Volumes/Castile/HackerProj/denoiser/denoiser/solver.py", line 190, in train
    self._serialize()
  File "/Volumes/Castile/HackerProj/denoiser/denoiser/solver.py", line 74, in _serialize
    package['model'] = serialize_model(self.model)
                       ^^^^^^^^^^^^^^^^^^^^^^^^^^^
  File "/Volumes/Castile/HackerProj/denoiser/denoiser/utils.py", line 64, in serialize_model
    args, kwargs = model._init_args_kwargs
                   ^^^^^^^^^^^^^^^^^^^^^^^
  File "/Volumes/Toys/Factory/anaconda3/envs/dnoise/lib/python3.11/site-packages/torch/nn/modules/module.py", line 1695, in __getattr__
    raise AttributeError(f"'{type(self).__name__}' object has no attribute '{name}'")
AttributeError: 'ConvTasNet' object has no attribute '_init_args_kwargs'
