[2023-12-08 10:55:50,051][__main__][INFO] - For logs, checkpoints and samples check /Volumes/Castile/HackerProj/denoiser
[2023-12-08 10:55:54,009][denoiser.solver][INFO] - ----------------------------------------------------------------------
[2023-12-08 10:55:54,009][denoiser.solver][INFO] - Training...
[2023-12-08 10:55:57,539][__main__][ERROR] - Some error happened
Traceback (most recent call last):
  File "/Volumes/Castile/HackerProj/denoiser/train.py", line 123, in main
    _main(args)
  File "/Volumes/Castile/HackerProj/denoiser/train.py", line 116, in _main
    run(args)
  File "/Volumes/Castile/HackerProj/denoiser/train.py", line 97, in run
    solver.train()
  File "/Volumes/Castile/HackerProj/denoiser/denoiser/solver.py", line 140, in train
    train_loss = self._run_one_epoch(epoch)  ##########################
                 ^^^^^^^^^^^^^^^^^^^^^^^^^^
  File "/Volumes/Castile/HackerProj/denoiser/denoiser/solver.py", line 196, in _run_one_epoch
    for i, data in enumerate(self.tr_loader):
  File "/Volumes/Toys/Factory/anaconda3/envs/dnoise/lib/python3.11/site-packages/torch/utils/data/dataloader.py", line 630, in __next__
    data = self._next_data()
           ^^^^^^^^^^^^^^^^^
  File "/Volumes/Toys/Factory/anaconda3/envs/dnoise/lib/python3.11/site-packages/torch/utils/data/dataloader.py", line 1345, in _next_data
    return self._process_data(data)
           ^^^^^^^^^^^^^^^^^^^^^^^^
  File "/Volumes/Toys/Factory/anaconda3/envs/dnoise/lib/python3.11/site-packages/torch/utils/data/dataloader.py", line 1371, in _process_data
    data.reraise()
  File "/Volumes/Toys/Factory/anaconda3/envs/dnoise/lib/python3.11/site-packages/torch/_utils.py", line 694, in reraise
    raise exception
TypeError: Caught TypeError in DataLoader worker process 0.
Original Traceback (most recent call last):
  File "/Volumes/Toys/Factory/anaconda3/envs/dnoise/lib/python3.11/site-packages/torch/utils/data/_utils/worker.py", line 308, in _worker_loop
    data = fetcher.fetch(index)
           ^^^^^^^^^^^^^^^^^^^^
  File "/Volumes/Toys/Factory/anaconda3/envs/dnoise/lib/python3.11/site-packages/torch/utils/data/_utils/fetch.py", line 54, in fetch
    return self.collate_fn(data)
           ^^^^^^^^^^^^^^^^^^^^^
  File "/Volumes/Toys/Factory/anaconda3/envs/dnoise/lib/python3.11/site-packages/torch/utils/data/_utils/collate.py", line 265, in default_collate
    return collate(batch, collate_fn_map=default_collate_fn_map)
           ^^^^^^^^^^^^^^^^^^^^^^^^^^^^^^^^^^^^^^^^^^^^^^^^^^^^^
  File "/Volumes/Toys/Factory/anaconda3/envs/dnoise/lib/python3.11/site-packages/torch/utils/data/_utils/collate.py", line 142, in collate
    return [collate(samples, collate_fn_map=collate_fn_map) for samples in transposed]  # Backwards compatibility.
           ^^^^^^^^^^^^^^^^^^^^^^^^^^^^^^^^^^^^^^^^^^^^^^^^^^^^^^^^^^^^^^^^^^^^^^^^^^^
  File "/Volumes/Toys/Factory/anaconda3/envs/dnoise/lib/python3.11/site-packages/torch/utils/data/_utils/collate.py", line 142, in <listcomp>
    return [collate(samples, collate_fn_map=collate_fn_map) for samples in transposed]  # Backwards compatibility.
            ^^^^^^^^^^^^^^^^^^^^^^^^^^^^^^^^^^^^^^^^^^^^^^^
  File "/Volumes/Toys/Factory/anaconda3/envs/dnoise/lib/python3.11/site-packages/torch/utils/data/_utils/collate.py", line 150, in collate
    raise TypeError(default_collate_err_msg_format.format(elem_type))
TypeError: default_collate: batch must contain tensors, numpy arrays, numbers, dicts or lists; found <class 'NoneType'>

