[2023-12-06 17:17:12,757][__main__][INFO] - For logs, checkpoints and samples check /Volumes/Castile/HackerProj/denoiser
[2023-12-06 17:17:15,850][denoiser.solver][INFO] - ----------------------------------------------------------------------
[2023-12-06 17:17:15,850][denoiser.solver][INFO] - Training...
[2023-12-06 17:17:19,675][__main__][ERROR] - Some error happened
Traceback (most recent call last):
  File "/Volumes/Castile/HackerProj/denoiser/train.py", line 123, in main
    _main(args)
  File "/Volumes/Castile/HackerProj/denoiser/train.py", line 116, in _main
    run(args)
  File "/Volumes/Castile/HackerProj/denoiser/train.py", line 97, in run
    solver.train()
  File "/Volumes/Castile/HackerProj/denoiser/denoiser/solver.py", line 140, in train
    train_loss = self._run_one_epoch(epoch)  #################
                 ^^^^^^^^^^^^^^^^^^^^^^^^^^
  File "/Volumes/Castile/HackerProj/denoiser/denoiser/solver.py", line 210, in _run_one_epoch
    estimate = self.dmodel(noisy) ########################
               ^^^^^^^^^^^^^^^^^^
  File "/Volumes/Toys/Factory/anaconda3/envs/dnoise/lib/python3.11/site-packages/torch/nn/modules/module.py", line 1518, in _wrapped_call_impl
    return self._call_impl(*args, **kwargs)
           ^^^^^^^^^^^^^^^^^^^^^^^^^^^^^^^^
  File "/Volumes/Toys/Factory/anaconda3/envs/dnoise/lib/python3.11/site-packages/torch/nn/modules/module.py", line 1527, in _call_impl
    return forward_call(*args, **kwargs)
           ^^^^^^^^^^^^^^^^^^^^^^^^^^^^^
  File "/Volumes/Castile/HackerProj/denoiser/denoiser/ConvTasnet1.py", line 63, in forward
    reshaped_frames = frames.reshape(*desired_size)
                      ^^^^^^^^^^^^^^^^^^^^^^^^^^^^^
RuntimeError: shape '[20, 128, -1]' is invalid for input of size 6879600
